Workbook

Sheet Table of Contents
C7: Worksheets | G7: Description
C9: Register Map | G9: Lists the ADS1220 register map fields, descriptions, and the corresponding read/write commands
C11: PGA Common-Mode Range | G11: Calculates if a given set of input voltages are within the PGA's input range limitations
C13: Code-to-Voltage Conversion | G13: Converts ADC codes to their corresponding voltages
C15: Code-to-Temperature Conversion | G15: Converts the integrated temp sensor output codes to their corresponsing temperatures
C17: Commands | G17: Identify the correct command byte for all available commands
C19: About | G19: Information about this tool
C21: Help | G21: Documentation and supporting links

Sheet Register Map
O5: Table of Contents
P7: Legend
O8: Input = | P8: #
O9: Result = | P9: #
O10: Static Value = | P10: #
O11: Logic High = | P11: #
O12: Logic Low = | P12: #
O13: Non-Default = | P13: #
I14: Configure register settings
B16: Address (Hex) | C16: Read / Write | D16: Default (Hex) | E16: Bit # | M16: Value | O16: Read Command | P16: Write Command
E17: 7 | F17: 6 | G17: 5 | H17: 4 | I17: 3 | J17: 2 | K17: 1 | L17: 0
A19: 0 | B19: =CONCATENATE("0x",DEC2HEX(A19,2)) -> 0x00 | C19: R/W | D19: 00h | E19: MUX[3:0] | I19: GAIN[2:0] | L19: PGA_BYPASS | M19: =CONCATENATE(DEC2HEX(L20+2*K20+4*J20+8*I20+16*H20+32*G20+64*F20+128*E20,2),"h") -> 3Eh | O19: 20h | P19: =CONCATENATE("40h, ",M19) -> 40h, 3Eh
E20: ='(RegMap)'!$D12 -> 0 | F20: ='(RegMap)'!$D13 -> 0 | G20: ='(RegMap)'!$D14 -> 1 | H20: ='(RegMap)'!$D15 -> 1 | I20: ='(RegMap)'!$D35 -> 1 | J20: ='(RegMap)'!$D36 -> 1 | K20: ='(RegMap)'!$D37 -> 1 | L20: ='(RegMap)'!$D48 -> 0
E21: AINP = AIN1, AINN = AIN2 | I21: 128 V/V | L21: PGA enabled (default)
A23: =1+A19 -> 1 | B23: =CONCATENATE("0x",DEC2HEX(A23,2)) -> 0x01 | C23: R/W | D23: 00h | E23: DR[2:0] | H23: MODE[1:0] | J23: CM | K23: TS | L23: BCS | M23: =CONCATENATE(DEC2HEX(L24+2*K24+4*J24+8*I24+16*H24+32*G24+64*F24+128*E24,2),"h") -> #N/A | O23: 24h | P23: =CONCATENATE("44h, ",M23) -> #N/A
E24: ='(RegMap)'!$H12 -> #N/A | F24: ='(RegMap)'!$H13 -> #N/A | G24: ='(RegMap)'!$H14 -> #N/A | H24: ='(RegMap)'!$H26 -> 0 | I24: ='(RegMap)'!$H27 -> 1 | J24: ='(RegMap)'!$H34 -> 0 | K24: ='(RegMap)'!$H39 -> 0 | L24: ='(RegMap)'!$H44 -> 0
E25: 20 SPS (default) | H25: Duty-cycle mode | J25: Single-shot mode (default) | K25: Disables temp sensor (default) | L25: Current sources off (default)
A27: =1+A23 -> 2 | B27: =CONCATENATE("0x",DEC2HEX(A27,2)) -> 0x02 | C27: R/W | D27: 00h | E27: VREF[1:0] | G27: 50/60[1:0] | I27: PSW | J27: IDAC[2:0] | M27: =CONCATENATE(DEC2HEX(L28+2*K28+4*J28+8*I28+16*H28+32*G28+64*F28+128*E28,2),"h") -> 47h | O27: 28h | P27: =CONCATENATE("48h, ",M27) -> 48h, 47h
E28: ='(RegMap)'!$L12 -> 0 | F28: ='(RegMap)'!$L13 -> 1 | G28: ='(RegMap)'!$L21 -> 0 | H28: ='(RegMap)'!$L22 -> 0 | I28: ='(RegMap)'!$L29 -> 0 | J28: ='(RegMap)'!$L35 -> 1 | K28: ='(RegMap)'!$L36 -> 1 | L28: ='(RegMap)'!$L37 -> 1
E29: External reference using REFP0 and REFN0 inputs | G29: No 50-Hz or 60-Hz rejection (default) | I29: Switch is always open (default) | J29: 1500 µA
A31: =1+A27 -> 3 | B31: =CONCATENATE("0x",DEC2HEX(A31,2)) -> 0x03 | C31: R/W | D31: 00h | E31: I1MUX[2:0] | H31: I2MUX[2:0] | K31: DRDYM | L31: --- | M31: =CONCATENATE(DEC2HEX(L32+2*K32+4*J32+8*I32+16*H32+32*G32+64*F32+128*E32,2),"h") -> A4h | O31: 2Ch | P31: =CONCATENATE("4Ch, ",M31) -> 4Ch, A4h
E32: ='(RegMap)'!$P12 -> 1 | F32: ='(RegMap)'!$P13 -> 0 | G32: ='(RegMap)'!$P14 -> 1 | H32: ='(RegMap)'!$P26 -> 0 | I32: ='(RegMap)'!$P27 -> 0 | J32: ='(RegMap)'!$P28 -> 1 | K32: ='(RegMap)'!$P39 -> 0 | L32: 0
E33: IDAC1 connected to REFP0 | H33: IDAC2 connected to AIN0/REFP1 | K33: Dedicated DRDY pin only (default) | L33: Reserved

Sheet (RegMap)
D6: From Reg Map | H6: Calculated (to Reg Map)
B8: ='Register Map'!$B19 -> 0x00 | F8: ='Register Map'!$B23 -> 0x01 | J8: ='Register Map'!$B27 -> 0x02 | N8: ='Register Map'!$B31 -> 0x03 | S8: Useful Formulas
C10: ='Register Map'!E21 -> AINP = AIN1, AINN = AIN2 | D10: =VLOOKUP(C10,C16:D31,2,FALSE()) -> 11 | G10: =IFERROR('Register Map'!E25,IF(G24=G29,G68,IF(G24=G30,G76,G60))) -> 20 SPS (default) | H10: =VLOOKUP(G10,G15:H22,2,FALSE()) -> #N/A | K10: ='Register Map'!E29 -> External reference using REFP0 and REFN0 inputs | L10: =VLOOKUP(K10,K14:L22,2,FALSE()) -> 1 | O10: ='Register Map'!E33 -> IDAC1 connected to REFP0 | P10: =VLOOKUP(O10,O15:P22,2,FALSE()) -> 101 | S10: ValueBelowCurrentCell
C11: ='Register Map'!E19 -> MUX[3:0] | D11: =IF(ISODD(BIN2DEC(D10)/2^2),1,0) -> 0 | G11: ='Register Map'!E$23 -> DR[2:0] | H11: =IF(ISODD(BIN2DEC(H10)/2^2),1,0) -> #N/A | K11: ='Register Map'!E27 -> VREF[1:0] | L11: =IF(ISODD(BIN2DEC(L10)/2^2),1,0) -> 0 | O11: ='Register Map'!E31 -> I1MUX[2:0] | P11: =IF(ISODD(BIN2DEC(P10)/2^2),1,0) -> 1 | S11: CELL("contents",INDIRECT(ADDRESS(ROW()+1, COLUMN())))
C12: Bit 3 | D12: =IF(ISODD(BIN2DEC(D10)/2^3),1,0) -> 0 | G12: Bit 2 | H12: =IF(ISODD(BIN2DEC(H10)/2^2),1,0) -> #N/A | K12: Bit 1 | L12: =IF(ISODD(BIN2DEC(L10)/2^1),1,0) -> 0 | O12: Bit 2 | P12: =IF(ISODD(BIN2DEC(P10)/2^2),1,0) -> 1
C13: Bit 2 | D13: =IF(ISODD(BIN2DEC(D10)/2^2),1,0) -> 0 | G13: Bit 1 | H13: =IF(ISODD(BIN2DEC(H10)/2^1),1,0) -> #N/A | K13: Bit 0 | L13: =IF(ISODD(BIN2DEC(L10)/2^0),1,0) -> 1 | O13: Bit 1 | P13: =IF(ISODD(BIN2DEC(P10)/2^1),1,0) -> 0 | S13: DefaultRegisterValue
C14: Bit 1 | D14: =IF(ISODD(BIN2DEC(D10)/2^1),1,0) -> 1 | G14: Bit 0 | H14: =IF(ISODD(BIN2DEC(H10)/2^0),1,0) -> #N/A | K14: Internal 2.048-V reference (default) | L14: 0 | O14: Bit 0 | P14: =IF(ISODD(BIN2DEC(P10)/2^0),1,0) -> 1 | S14: 'CELL("contents",INDIRECT(ADDRESS(ROW(),COLUMN($E$11))))
C15: Bit 0 | D15: =IF(ISODD(BIN2DEC(D10)/2^0),1,0) -> 1 | G15: =IF($G$24=$G$29,G68,IF($G$24=$G$30,G76,G60)) -> 5 SPS (default) | H15: 0 | K15: External reference using REFP0 and REFN0 inputs | L15: 1 | O15: IDAC1 disabled (default) | P15: 0
C16: AINP = AIN0, AINN = AIN1 (default) | D16: 0 | G16: =IF($G$24=$G$29,G69,IF($G$24=$G$30,G77,G61)) -> 11.25 SPS | H16: 1 | K16: External reference using AIN0/REFP1 and AIN3/REFN1 inputs | L16: 10 | O16: IDAC1 connected to AIN0/REFP1 | P16: 1 | S16: Bit_Num
C17: AINP = AIN0, AINN = AIN2 | D17: 1 | G17: =IF($G$24=$G$29,G70,IF($G$24=$G$30,G78,G62)) -> 22.5 SPS | H17: 10 | K17: Analog supply (AVDD – AVSS) | L17: 11 | O17: IDAC1 connected to AIN1 | P17: 10 | S17: 'CELL("contents",INDIRECT(ADDRESS(ROW('Register Map'!$F$12),COLUMN())))
C18: AINP = AIN0, AINN = AIN3 | D18: 10 | G18: =IF($G$24=$G$29,G71,IF($G$24=$G$30,G79,G63)) -> 44 SPS | H18: 11 | O18: IDAC1 connected to AIN2 | P18: 11
C19: AINP = AIN1, AINN = AIN2 | D19: 11 | G19: =IF($G$24=$G$29,G72,IF($G$24=$G$30,G80,G64)) -> 82.5 SPS | H19: 100 | K19: ='Register Map'!G29 -> No 50-Hz or 60-Hz rejection (default) | L19: =VLOOKUP(K19,K23:L31,2,FALSE()) -> 0 | O19: IDAC1 connected to AIN3/REFN1 | P19: 100 | S19: Read Command (decimal)
C20: AINP = AIN1, AINN = AIN3 | D20: 100 | G20: =IF($G$24=$G$29,G73,IF($G$24=$G$30,G81,G65)) -> 150 SPS | H20: 101 | K20: ='Register Map'!G27 -> 50/60[1:0] | L20: =IF(ISODD(BIN2DEC(L19)/2^2),1,0) -> 0 | O20: IDAC1 connected to REFP0 | P20: 101 | S20: 32
C21: AINP = AIN2, AINN = AIN3 | D21: 101 | G21: =IF($G$24=$G$29,G74,IF($G$24=$G$30,G82,G66)) -> 250 SPS | H21: 110 | K21: Bit 1 | L21: =IF(ISODD(BIN2DEC(L19)/2^1),1,0) -> 0 | O21: IDAC1 connected to REFN0 | P21: 110
C22: AINP = AIN1, AINN = AIN0 | D22: 110 | G22: =IF($G$24=$G$29,G75,IF($G$24=$G$30,G83,G67)) -> 0 | H22: 111 | K22: Bit 0 | L22: =IF(ISODD(BIN2DEC(L19)/2^0),1,0) -> 0 | O22: Reserved | P22: 111 | S22: Write Command (decimal)
C23: AINP = AIN3, AINN = AIN2 | D23: 111 | K23: No 50-Hz or 60-Hz rejection (default) | L23: 0 | S23: 64
C24: AINP = AIN0, AINN = AVSS | D24: 1000 | G24: ='Register Map'!H25 -> Duty-cycle mode | H24: =VLOOKUP(G24,G28:H36,2,FALSE()) -> 1 | K24: Simultaneous 50-Hz and 60-Hz rejection | L24: 1 | O24: ='Register Map'!H33 -> IDAC2 connected to AIN0/REFP1 | P24: =VLOOKUP(O24,O29:P36,2,FALSE()) -> 1
C25: AINP = AIN1, AINN = AVSS | D25: 1001 | G25: ='Register Map'!H$23 -> MODE[1:0] | H25: =IF(ISODD(BIN2DEC(H24)/2^2),1,0) -> 0 | K25: 50-Hz rejection only | L25: 10 | O25: ='Register Map'!H31 -> I2MUX[2:0] | P25: =IF(ISODD(BIN2DEC(P24)/2^2),1,0) -> 0
C26: AINP = AIN2, AINN = AVSS | D26: 1010 | G26: Bit 1 | H26: =IF(ISODD(BIN2DEC(H24)/2^1),1,0) -> 0 | K26: 60-Hz rejection only | L26: 11 | O26: Bit 2 | P26: =IF(ISODD(BIN2DEC(P24)/2^2),1,0) -> 0 | S26: Device Options
C27: AINP = AIN3, AINN = AVSS | D27: 1011 | G27: Bit 0 | H27: =IF(ISODD(BIN2DEC(H24)/2^0),1,0) -> 1 | O27: Bit 1 | P27: =IF(ISODD(BIN2DEC(P24)/2^1),1,0) -> 0 | S27: ADS124S08
C28: (V(REFPx) – V(REFNx)) / 4 monitor (PGA bypassed) | D28: 1100 | G28: Normal mode (default) | H28: 0 | K28: ='Register Map'!I29 -> Switch is always open (default) | L28: =VLOOKUP(K28,K30:L31,2,FALSE()) -> 0 | O28: Bit 0 | P28: =IF(ISODD(BIN2DEC(P24)/2^0),1,0) -> 1 | S28: ADS124S06
C29: (AVDD – AVSS) / 4 monitor (PGA bypassed) | D29: 1101 | G29: Duty-cycle mode | H29: 1 | K29: ='Register Map'!I27 -> PSW | L29: =IF(ISODD(BIN2DEC(L28)/2^0),1,0) -> 0 | O29: IDAC2 disabled (default) | P29: 0 | S29: ADS114S08
C30: AINP and AINN shorted to (AVDD + AVSS) / 2 | D30: 1110 | G30: Turbo mode | H30: 10 | K30: Switch is always open (default) | L30: 0 | O30: IDAC2 connected to AIN0/REFP1 | P30: 1 | S30: ADS114S06
C31: Reserved | D31: 1111 | G31: Reserved | H31: 11 | K31: Switch closes after START/SYNC command, opens after POWERDOWN command | L31: 1 | O31: IDAC2 connected to AIN1 | P31: 10
O32: IDAC2 connected to AIN2 | P32: 11
C33: ='Register Map'!I21 -> 128 V/V | D33: =VLOOKUP(C33,C38:D45,2,FALSE()) -> 111 | G33: ='Register Map'!J25 -> Single-shot mode (default) | H33: =VLOOKUP(G33,G35:H36,2,FALSE()) -> 0 | K33: ='Register Map'!J29 -> 1500 µA | L33: =VLOOKUP(K33,K38:L45,2,FALSE()) -> 111 | O33: IDAC2 connected to AIN3/REFN1 | P33: 100
C34: ='Register Map'!I19 -> GAIN[2:0] | D34: =IF(ISODD(BIN2DEC(D33)/2^2),1,0) -> 1 | G34: ='Register Map'!J$23 -> CM | H34: =IF(ISODD(BIN2DEC(H33)/2^0),1,0) -> 0 | K34: ='Register Map'!J27 -> IDAC[2:0] | L34: =IF(ISODD(BIN2DEC(L33)/2^2),1,0) -> 1 | O34: IDAC2 connected to REFP0 | P34: 101
C35: Bit 2 | D35: =IF(ISODD(BIN2DEC(D33)/2^2),1,0) -> 1 | G35: Single-shot mode (default) | H35: 0 | K35: Bit 2 | L35: =IF(ISODD(BIN2DEC(L33)/2^2),1,0) -> 1 | O35: IDAC2 connected to REFN0 | P35: 110
C36: Bit 1 | D36: =IF(ISODD(BIN2DEC(D33)/2^1),1,0) -> 1 | G36: Continuous conversion mode | H36: 1 | K36: Bit 1 | L36: =IF(ISODD(BIN2DEC(L33)/2^1),1,0) -> 1 | O36: Reserved | P36: 111
C37: Bit 0 | D37: =IF(ISODD(BIN2DEC(D33)/2^0),1,0) -> 1 | K37: Bit 0 | L37: =IF(ISODD(BIN2DEC(L33)/2^0),1,0) -> 1
C38: 1 V/V (default) | D38: 0 | G38: ='Register Map'!K25 -> Disables temp sensor (default) | H38: =VLOOKUP(G38,G40:H41,2,FALSE()) -> 0 | K38: Off (default) | L38: 0 | O38: ='Register Map'!K33 -> Dedicated DRDY pin only (default) | P38: =VLOOKUP(O38,O40:P41,2,FALSE()) -> 0
C39: 2 V/V | D39: 1 | G39: ='Register Map'!K$23 -> TS | H39: =IF(ISODD(BIN2DEC(H38)/2^0),1,0) -> 0 | K39: 10 µA | L39: 1 | O39: ='Register Map'!K31 -> DRDYM | P39: =IF(ISODD(BIN2DEC(P38)/2^0),1,0) -> 0
C40: 4 V/V | D40: 10 | G40: Disables temp sensor (default) | H40: 0 | K40: 50 µA | L40: 10 | O40: Dedicated DRDY pin only (default) | P40: 0
C41: 8 V/V | D41: 11 | G41: Enables temp sensor | H41: 1 | K41: 100 µA | L41: 11 | O41: Use both DOUT/DRDY and DRDY pins | P41: 1
C42: 16 V/V | D42: 100 | K42: 250 µA | L42: 100
C43: 32 V/V | D43: 101 | G43: ='Register Map'!L25 -> Current sources off (default) | H43: =VLOOKUP(G43,G45:H46,2,FALSE()) -> 0 | K43: 500 µA | L43: 101
C44: 64 V/V | D44: 110 | G44: ='Register Map'!L$23 -> BCS | H44: =IF(ISODD(BIN2DEC(H43)/2^0),1,0) -> 0 | K44: 1000 µA | L44: 110
C45: 128 V/V | D45: 111 | G45: Current sources off (default) | H45: 0 | K45: 1500 µA | L45: 111
G46: Current sources on | H46: 1
C47: ='Register Map'!L21 -> PGA enabled (default) | D47: =VLOOKUP(C47,C49:D50,2,FALSE()) -> 0
...

Sheet PGA Common-Mode Range
S5: Table of Contents
C6: 1) Configure ADC parameters
C7: PGA Gain | T7: Legend
C8: PGA Gain | D8: 128 | E8: V/V | L8: PGA INPUT | O8: PGA OUTPUT | S8: Input = | T8: #
C9: Supply Voltage(s) | S9: Result = | T9: #
B10: =CONCATENATE(ROUND($E$103,4)," V ≤ ") -> 2.3 V ≤ | C10: AVDD | D10: 3.3 | E10: V | F10: =CONCATENATE(" ≤ ", ROUND($E$102,4), " V") -> ≤ 5.5 V | S10: Invalid Parameter = | T10: #
B11: =CONCATENATE(ROUND($E$105,4)," V ≤ ") -> -2.75 V ≤ | C11: AVSS | D11: 0 | E11: V | F11: =CONCATENATE(" ≤ ", ROUND($E$104,4), " V") -> ≤ 0 V
C12: Reference Voltage(s)
B13: =CONCATENATE(ROUND($E$109,4)," V ≤ ") -> 1,8765 V ≤ | C13: VREFP | D13: 2.0565 | E13: V | F13: =CONCATENATE(" ≤ ", ROUND($E$108,4), " V") -> ≤ 3,4 V
B14: =CONCATENATE(ROUND($E$111,4)," V ≤ ") -> -0.1 V ≤ | C14: VREFN | D14: 1.1265 | E14: V | F14: =CONCATENATE(" ≤ ", ROUND($E$110,4), " V") -> ≤ 1,3065 V
C16: 2) Define input voltages
C17: Input Voltage
C18: Input Mode | D18: Differential/CM Voltages
B19: =CONCATENATE(ROUND(IF(INPUT_MODE=C38,$E$83,$E$95),4)," V ≤ ") -> -0,0073 V ≤ | C19: =VLOOKUP(INPUT_MODE,C38:E39,2,FALSE()) -> VIN_DIFF | D19: 0.0015 | E19: V | F19: =CONCATENATE(" ≤ ", ROUND(IF(INPUT_MODE=C38,$E$82,$E$94),4), " V") -> ≤ 0,0073 V
B20: =CONCATENATE(ROUND(IF(INPUT_MODE=C38,$E$85,$E$99),4)," V ≤ ") -> 0,825 V ≤ | C20: =VLOOKUP(INPUT_MODE,C38:E39,3,FALSE()) -> VIN_CM | D20: 1.12575 | E20: V | F20: =CONCATENATE(" ≤ ", ROUND(IF(INPUT_MODE=C38,$E$84,$E$98),4), " V") -> ≤ 3,004 V
C22: 3) Check for errors
C23: Error messages | L23: PGA Input | P23: PGA Output
C24: V(AVDD-AVSS) | D24: ← Supply voltage(s) is out-of-range! | K24: =CONCATENATE(ROUND('PGA Common-Mode Range'!$E$83,4)," V ≤ ") -> 1,1177 V ≤ | L24: VINP | M24: =VINP -> 1.1265 | N24: =CONCATENATE(" ≤ ", ROUND('PGA Common-Mode Range'!$E$82,4), " V") -> ≤ 1,1323 V | O24: =CONCATENATE(ROUND(AVSS+Swing_to_Rail,4)," V ≤ ") -> 0,2 V ≤ | P24: VOUTP | Q24: =VOUTP_CLAMP -> 1.22175 | R24: =CONCATENATE(" ≤ ",ROUND(AVDD-Swing_to_Rail,4), " V") -> ≤ 3,1 V
C25: V(REFP-REFN) | D25: ← Reference voltage(s) is out-of-range! | L25: VINN | M25: =VINN -> 1.125 | P25: VOUTN | Q25: =VOUTN_CLAMP -> 1.02975
C26: VIN_DIFF | D26: =CONCATENATE("← Input exceeds the maximum differential voltage (±",ROUND('PGA Common-Mode Range'!E94,5), " V)!") -> ← Input exceeds the maximum differential voltage (±0,00727 V)! | K26: =CONCATENATE(ROUND('PGA Common-Mode Range'!$E$95,4)," V ≤ ") -> -0,0073 V ≤ | L26: VIN_DIFF | M26: =VIN_DIFF -> 0.0015 | N26: =CONCATENATE(" ≤ ", ROUND('PGA Common-Mode Range'!$E$94,4), " V") -> ≤ 0,0073 V | O26: =CONCATENATE(ROUND(-POS_FULL_SCALE,4)," V ≤ ") -> -0,93 V ≤ | P26: VOUT_DIFF | Q26: =VOUT_DIFF_CLAMPED -> 0.192 | R26: =CONCATENATE(" ≤ ",ROUND(POS_FULL_SCALE,4), " V") -> ≤ 0,93 V
C27: VINP | D27: ← Positive input voltage is out-of-range! | K27: =CONCATENATE(ROUND('PGA Common-Mode Range'!$E$99,4)," V ≤ ") -> 0,825 V ≤ | L27: VIN_CM | M27: =VCM -> 1.12575 | N27: =CONCATENATE(" ≤ ",ROUND('PGA Common-Mode Range'!$E$98,4), " V") -> ≤ 3,004 V | P27: VOUT_CM | Q27: =VOUT_CM_CLAMPED -> 1.12575
C28: VINN | D28: ← Negative input voltage is out-of-range!
B34: ↓ CM Range Calculations ↓
N36: Plot Data
C37: Input Modes | D37: Label 1 | E37: Label 2
C38: Absolute Voltages | D38: VINP | E38: VINN | O38: X | P38: Y
C39: Differential/CM Voltages | D39: VIN_DIFF | E39: VIN_CM | N39: Center Line | O39: 1 | P39: =AVSS-0.5 -> -0.5
O40: 1 | P40: =AVDD+0.5 -> 3.8
C41: Values
C42: Selected Gain | E42: ='PGA Common-Mode Range'!D8 -> 128 | F42: * These values are provided by the user, expect VINP/VINN which are computed when user specifies the input signal as a differential + CM voltage | N42: AVDD | O42: 0 | P42: =AVDD -> 3.3
C43: AVDD | E43: ='PGA Common-Mode Range'!D10 -> 3.3 | O43: 1.8 | P43: =AVDD -> 3.3
C44: AVSS | E44: ='PGA Common-Mode Range'!D11 -> 0 | N44: AVSS | O44: =O42 -> 0 | P44: =AVSS -> 0
C45: VREFP | E45: ='PGA Common-Mode Range'!D13 -> 2.0565 | O45: =O43 -> 1.8 | P45: =AVSS -> 0
C46: VREFN | E46: ='PGA Common-Mode Range'!D14 -> 1.1265
C47: VINP | E47: =IF(INPUT_MODE=C38,D19,D20+D19/2) -> 1.1265 | N47: VINP | O47: 0.4 | P47: =VINP -> 1.1265
C48: VINN | E48: =IF(INPUT_MODE=C38,D20,D20-D19/2) -> 1.125 | O48: 0.6 | P48: =VINP -> 1.1265
N49: VINN | O49: =O47 -> 0.4 | P49: =VINN -> 1.125
C50: Gain Look-up Table | O50: =O48 -> 0.6 | P50: =VINN -> 1.125
C51: Gain | D51: PGA Gain | E51: SC Gain | N51: Diff I/P | O51: =(O48+O47)/2 -> 0.5 | P51: =P47 -> 1.1265
C52: BYPASSED | D52: 1 | E52: 1 | O52: =O51 -> 0.5 | P52: =P49 -> 1.125
...

Sheet Code-to-Voltage Conversion
L5: Table of Contents
M7: Legend
B8: ADC Parameters | F8: ADC Input Range & Least Significant Bit (LSB) Size | L8: Input = | M8: #
B9: PGA Gain | C9: 1 | D9: [V/V] | E9: → | F9: Differential Input Range | G9: =(C50/2) -> 2.5 | H9: [V] | L9: Result = | M9: #
B10: Reference Voltage | C10: 2.5 | D10: [V] | F10: LSB size | G10: =LSB_Size_V*1000000000 -> 298.02322 | H10: [nV] | L10: Invalid Parameter = | M10: #
B13: ADC Output Code (2's Complement) | F13: Input Voltage RTI (1)
B14: FFFFF | D14: [Hex] | E14: → | F14: =G38 -> 0.3124997 | H14: [V]
B15: =IF(D14="[Hex]",CONCATENATE("Input a hex value between ",Min_Code_Hex," and ",Max_Code_Hex),CONCATENATE("Input a decimal value between ",Min_Code_Decimal," and ",Max_Code_Decimal)) -> Input a hex value between 800000 and 7FFFFF
B17: Differential Input Voltage RTI (1) | F17: Ideal Output Code (2)
B18: 0.073 | D18: [V] | E18: → | F18: =G48 -> 03BCD3 | H18: [Hex]
F20: Output Code Clipped!
B21: Notes:
B22: (1) "RTI" means "referred to input" (i.e. the voltage applied to the input pins, prior to the PGA gain)
B23: (2) Ideal output code (i.e. ignoring the effects of noise, INL, calibration, etc.)
A31: ↓ Calculations ↓
B33: Code: | C33: =B14 -> FFFFF | F33: Voltage Conversion
B34: Input Type: | C34: =D14 -> [Hex] | F34: Is Negative? | G34: =IF(Input_Type="[Decimal]",IF(Code<0,TRUE(),FALSE()),IF(Input_Type="[Hex]",ISODD(HEX2DEC(Code)/2^(Num_Bits-1)),"Error")) -> FALSE
B35: Reference Voltage: | C35: =C10 -> 2.5 | F35: Decimal Value: | G35: =IF(Input_Type="[Decimal]",Code,IF(Input_Type="[Hex]",IF(G34,(HEX2DEC(Code)-2^Num_Bits),HEX2DEC(Code)))) -> 1048575
B36: PGA Gain: | C36: =C9 -> 1 | F36: Voltage [V]: | G36: =IF(valid?,Decimal_Value*LSB_Size_V,"(Invalid Code)") -> #VALUE!
F37: Selected Units: | G37: =H14 -> [V]
B38: Code Validation | F38: =CONCATENATE("Voltage in ",G37,":") -> Voltage in [V]: | G38: =IF(valid?,G36/VLOOKUP(G37,F53:G56,2,FALSE()),"(Invalid Code)") -> #VALUE!
B39: Number of Bits: | C39: 24
B40: Number of hex digits: | C40: =ROUNDUP(Num_Bits/4,0) -> 6 | F40: Code Conversion
B41: Number of Codes: | C41: =2^Num_Bits -> 16777216 | F41: Selected Units: | G41: =D18 -> [V]
B42: Min Code: | C42: =-(2^(Num_Bits-1)) -> -8388608 | D42: =RIGHT(DEC2HEX(C42,Number_of_hex_digits),Number_of_hex_digits) -> 800000 | F42: Voltage [V]: | G42: =B18*VLOOKUP(G41,F53:G56,2,FALSE()) -> 0.073
B43: Max Code: | C43: =2^(Num_Bits-1)-1 -> 8388607 | D43: =RIGHT(DEC2HEX(C43,Number_of_hex_digits),Number_of_hex_digits) -> 7FFFFF | F43: Voltage Out-of-Range? | G43: =OR((G42>Input_Range-LSB_Size_V),(G42<-Input_Range)) -> FALSE
B44: Is Number? | C44: =IF(Input_Type="[Hex]",ISNUMBER(HEX2DEC(Code)),IF(Input_Type="[Decimal]",ISNONTEXT(Code),"Developer Error")) -> TRUE | F44: Out-of-Range Direction: | G44: =IF(voltage_out_of_range?,IF(G42>=Input_Range,"POSITIVE",IF(G42<-Input_Range,"NEGATIVE","Developer Error")),"-") -> #VALUE!
B45: In Range? | C45: =IF(is_number?,IF(Input_Type="[Hex]",IF(HEX2DEC(Code)<(2^Num_Bits),TRUE(),FALSE()),(IF(Input_Type="[Decimal]",AND((Code>=Min_Code_Decimal),(Code<=Max_Code_Decimal)),FALSE())))) -> #VALUE! | F45: Decimal: | G45: =IF(G44="POSITIVE",Max_Code_Decimal,IF(G44="NEGATIVE",Min_Code_Decimal,ROUND(G42/(LSB_Size_V),0))) -> 244947
B46: Valid? | C46: =AND(is_number?,in_range?) -> #VALUE! | F46: Hex: | G46: =IF(G44="POSITIVE",Max_Code_Hex,IF(G44="NEGATIVE",Min_Code_Hex,RIGHT(DEC2HEX(ROUND(G42/(LSB_Size_V),0),Number_of_hex_digits),Number_of_hex_digits))) -> 03BCD3
F47: Output Type: | G47: =H18 -> [Hex]
B48: FSR/LSB Size Calculations | F48: Output Code: | G48: =IF(G47="[Hex]",G46,IF(G47="[Decimal]",G45,"Developer Error")) -> 03BCD3
B49: FSR Multiplier: | C49: 2
B50: FSR: | C50: =C35*FSR_Multiplier/C36 -> 5
B51: LSB Size: | C51: =C50/C41 -> 2.9802322e-07 | D51: [V]
F52: Units | G52: Multiplier
B53: ADC Parameter Validation | F53: [V] | G53: 1
F54: [mV] | G54: 0.001
B55: Vref Min: | C55: 0.75 | F55: [μV] | G55: 1e-06
B56: Vref Max: | C56: 5.5 | F56: [nV] | G56: 1e-09
B57: PGA gains:
...

Sheet Code-to-Temperature Conversion
B1: aa | C1: =B1 -> aa | D1: =C1 -> aa | E1: =D1 -> aa | F1: =E1 -> aa | G1: =F1 -> aa | H1: =G1 -> aa | I1: =H1 -> aa | J1: =I1 -> aa | ... Z1: =Y1 -> aa | AD1: =Z1 -> aa | AE1: =AD1 -> aa | AF1: =AE1 -> aa | AG1: =AF1 -> aa | AH1: =AG1 -> aa | AI1: =#ref! -> #NAME? | AJ1: =#ref! -> #NAME? | AK1: =AJ1 -> #NAME? | AL1: =AK1 -> #NAME? | AM1: =AL1 -> #NAME? | AN1: =AM1 -> #NAME? | AO1: =AN1 -> #NAME? | AP1: =AO1 -> #NAME? | AQ1: =AP1 -> #NAME? | AR1: =AQ1 -> #NAME? | AS1: =#ref! -> #NAME? | AT1: =#ref! -> #NAME? | AU1: =AT1 -> #NAME? | AV1: =AU1 -> #NAME? | AW1: =AV1 -> #NAME? | AX1: =AW1 -> #NAME? | AZ1: =AX1 -> #NAME? | BA1: =AZ1 -> #NAME? | BB1: =BA1 -> #NAME? | BC1: =BB1 -> #NAME? | BD1: =BC1 -> #NAME? | BE1: =BD1 -> #NAME?
AZ5: Table of Contents
BE7: Legend
B8: NOTE: Valid when using ADS1220 in Internal Temperature Sensor Mode (TS = '1') | AD8: Least Significant Bit (LSB) Size | BA8: Input = | BE8: #
AD9: LSB size | AI9: 0.03125 | AS9: [°C] | BA9: Result = | BE9: #
AY10: Invalid Parameter = | BE10: #
AZ11: Static Value = | BE11: #
B13: Input a hex value between 3B00h and 1000h
B14: 24-bit Data from Temp Sensor Measurement (2's Complement)
B15: Data 1 (MSB) | F15: Data 2 | J15: Data 3 | N15: Data 4 | R15: Data 5 | V15: Data 6 (LSB) | AD15: Code-to-Temperature Results
B16: 3 | F16: B | J16: 0 | N16: 0 | R16: 0 | V16: 0 | AA16: → | AD16: =S37 -> -40 | AJ16: [°C] | AN16: =S36 -> -1280 | AT16: [Decimal]
B17: =LEFT(HEX2BIN(B16,4),1) -> 0 | C17: =MID(HEX2BIN(B16,4),2,1) -> 0 | D17: =MID(HEX2BIN(B16,4),3,1) -> 1 | E17: =RIGHT(HEX2BIN(B16,4),1) -> 1 | F17: =LEFT(HEX2BIN(F16,4),1) -> 1 | G17: =MID(HEX2BIN(F16,4),2,1) -> 0 | H17: =MID(HEX2BIN(F16,4),3,1) -> 1 | I17: =RIGHT(HEX2BIN(F16,4),1) -> 1 | J17: =LEFT(HEX2BIN(J16,4),1) -> 0 | K17: =MID(HEX2BIN(J16,4),2,1) -> 0 | L17: =MID(HEX2BIN(J16,4),3,1) -> 0 | M17: =RIGHT(HEX2BIN(J16,4),1) -> 0 | N17: =LEFT(HEX2BIN(N16,4),1) -> 0 | O17: =MID(HEX2BIN(N16,4),2,1) -> 0 | P17: =MID(HEX2BIN(N16,4),3,1) -> 0 | Q17: =RIGHT(HEX2BIN(N16,4),1) -> 0 | R17: =LEFT(HEX2BIN(R16,4),1) -> 0 | S17: =MID(HEX2BIN(R16,4),2,1) -> 0 | T17: =MID(HEX2BIN(R16,4),3,1) -> 0 | U17: =RIGHT(HEX2BIN(R16,4),1) -> 0 | V17: =LEFT(HEX2BIN(V16,4),1) -> 0 | W17: =MID(HEX2BIN(V16,4),2,1) -> 0 | X17: =MID(HEX2BIN(V16,4),3,1) -> 0 | Y17: =RIGHT(HEX2BIN(V16,4),1) -> 0
F21: 14-bit temperature output
B23: ="Input a temperature between -40°C and 128°C" -> Input a temperature between -40°C and 128°C
B24: Temperature | AD24: Temperature-to-Code Results
B25: 128 | R25: [°C] | AA25: → | AD25: =S39 -> 4096 | AJ25: [Decimal] | AN25: =S40 -> 1000 | AT25: [Hex]
A34: ↓ Calculations ↓
B36: hex to dec (unsigned) | J36: =HEX2DEC(_xlfn.CONCAT(B16:Q16)) -> 15104 | N36: CtoT | P36: Decimal | S36: =IF(J46,J38,"(Invalid Code)") -> -1280 | X36: 0
B37: 2^13 | J37: =2^13 -> 8192 | P37: Temp | S37: =IF(J46,S36*AI9,"(Invalid Code)") -> -40 | X37: 1
B38: hex to dec (signed 14-bit) | J38: =IF(J36>J37,J36-2^14,J36) -> -1280 | X38: 2
N39: TtoC | P39: Decimal | S39: =B25/AI9 -> 4096 | X39: 3
B40: min(hex) | J40: 3B00 | P40: Hex | S40: =IF(B25>=0, DEC2HEX(S39,4),DEC2HEX((-2^14+S39),4)) -> 1000 | X40: 4
B41: min(dec) | J41: =IF(HEX2DEC(J40)<HEX2DEC(2000), HEX2DEC(J40), HEX2DEC(J40)-2^14) -> -1280 | X41: 5
B42: max(hex) | J42: 1000 | X42: 6
B43: max(dec) | J43: =IF(HEX2DEC(J42)<HEX2DEC(2000), HEX2DEC(J42), HEX2DEC(J42)-2^14) -> 4096 | X43: 7
X44: 8
X45: 9
B46: Isvalid? | J46: =IFERROR(IF(AND(J38>=J41,J38<=J43),TRUE(),FALSE()),FALSE()) -> TRUE | X46: A
X47: B
X48: C
X49: D
X50: E
X51: F

Sheet Commands
J5: Table of Contents
K7: Legend
B8: User Input | E8: Values to Write | J8: Input = | K8: #
B9: Start reading/writing at register number: | C9: 0 | D9: → | E9: rr (configuration register) (00 to 11) | F9: =DEC2BIN(C9, 2) -> 00 | J9: Result = | K9: #
B10: How many registers to read/write | C10: 1 | D10: → | E10: nn (number of bytes - 1) (00 to 11) | F10: =DEC2BIN(C10-1, 2) -> 00
B12: Command | C12: Description | F12: Command Byte
B13: WREG | C13: Write nn registers starting at address rr | F13: 0100 | G13: =_xlfn.CONCAT(F9,F10) -> 0000
B14: RREG | C14: Read nn registers starting at address rr | F14: 0010 | G14: =G13 -> 0000
B15: RESET | C15: Reset the ADC to its default settings | F15: 0000 | G15: 011x(1)
B16: START/SYNC | C16: Resets digital filter and start a new conversion | F16: 0000 | G16: 100x(1)
B17: POWERDOWN | C17: Power down ADC | F17: 0000 | G17: 001x(1)
B18: RDATA | C18: Read data | F18: 0001 | G18: xxxx(1)
B20: Notes:
B21: (1) x = don't care

Sheet About
E2: © Copyright 2022 Texas Instruments Incorporated. All rights reserved.
A5: Version Number | B5: 1.0.0 | L5: Table of Contents
A6: Created by | B6: Bryan Lizon & Joachim Wuerker
A35: Version History
A36: Version | B36: Change List Description
A37: 1.0.0 | B37: Initial Release

Sheet Help
A5: For any futher assistance on this tool, please post your question in the following forum - E2E Precision Data Converters Forum | R5: Table of Contents
A8: Getting Started with this tool ?
B10: 1. Reference the product datasheet, found at the URLs below, for information about the particular device.
C11: ADS1220: | E11: https://www.ti.com/product/ADS1220
B13: 2. Go to the Table of Contents for tool descriptions and links to specific worksheets.
C14: Link: | E14: Table of Contents
B16: 3.Use the "Legend" on each worksheet for guidance. The required inputs and calculated results typically follow the convention below:
C18: # | E18: = Input
C19: # | E19: = Result
